Workbook

Sheet Location
A1: No | B1: Barcode No. | C1: Item Name | D1: Rack Location | E1: Category-1 | F1: Category-2 | G1: QTY | H1: Date
A2: 1 | B2: 4905687380154 | C2: =VLOOKUP(B:B,DATA!A:B,2,0) -> ແປງທຳຄວາມສະອາດ 2 ຫົວ /0154 | D2: H01-L4-1 | E2: =VLOOKUP(B:B,DATA!A:C,3,0) -> CLEANING/BATH | F2: =VLOOKUP(B:B,DATA!A:D,4,0) -> bathroom supplies | G2: 3 | H2: 46044
A3: 2 | B3: 1234560026401 | C3: =VLOOKUP(B:B,DATA!A:B,2,0) -> ມີດຕັດເລັບສັດລ້ຽງ GP-2640 | D3: H01-L5-1 | E3: =VLOOKUP(B:B,DATA!A:C,3,0) -> SPORTS/LEISURE | F3: =VLOOKUP(B:B,DATA!A:D,4,0) -> PET | G3: 0
A4: 3 | B4: 1234560026333 | C4: =VLOOKUP(B:B,DATA!A:B,2,0) -> ເຊືອກຈູງຄໍສັດລ້ຽງ GP-2633 | D4: H01-L4-3 | E4: =VLOOKUP(B:B,DATA!A:C,3,0) -> SPORTS/LEISURE | F4: =VLOOKUP(B:B,DATA!A:D,4,0) -> PET | G4: 3
A5: 4 | B5: 6972854797297 | C5: =VLOOKUP(B:B,DATA!A:B,2,0) -> ກ່ອງໃສ່ເຄື່ອງອະເນກປະສົງ/DL3364 /7297 | D5: S10-L2-4 | E5: =VLOOKUP(B:B,DATA!A:C,3,0) -> stationery | F5: =VLOOKUP(B:B,DATA!A:D,4,0) -> desk storage | G5: 0
A6: 5 | B6: 6972854797303 | C6: =VLOOKUP(B:B,DATA!A:B,2,0) -> ກ່ອງໃສ່ເຄື່ອງອະເນກປະສົງ/DL3365 /7303 | D6: S10-L1-3 | E6: =VLOOKUP(B:B,DATA!A:C,3,0) -> stationery | F6: =VLOOKUP(B:B,DATA!A:D,4,0) -> desk storage | G6: 0
A7: 6 | B7: 6972854794616 | C7: =VLOOKUP(B:B,DATA!A:B,2,0) -> ກ່ອງໃສ່ເຄື່ອງອະເນກປະສົງ/DL3360 /4616 | D7: S10-L1-3 | E7: =VLOOKUP(B:B,DATA!A:C,3,0) -> stationery | F7: =VLOOKUP(B:B,DATA!A:D,4,0) -> desk storage | G7: 15
A8: 7 | B8: 6947860590019 | C8: =VLOOKUP(B:B,DATA!A:B,2,0) -> ກ່ອງເກັບເງິນ 6 inch/DL9001/0019 | D8: S01-L1-1 | E8: =VLOOKUP(B:B,DATA!A:C,3,0) -> stationery | F8: =VLOOKUP(B:B,DATA!A:D,4,0) -> desk storage | G8: 0
A9: 8 | B9: 6972854797181 | C9: =VLOOKUP(B:B,DATA!A:B,2,0) -> ກ່ອງໃສ່ບິກສໍ/DL3359 /7181 | D9: S01-L2-2 | E9: =VLOOKUP(B:B,DATA!A:C,3,0) -> stationery | F9: =VLOOKUP(B:B,DATA!A:D,4,0) -> desk storage | G9: 3
A10: 9 | B10: 6972081861839 | C10: =VLOOKUP(B:B,DATA!A:B,2,0) -> ແນວໃສ່ບິກສໍ/DL802F/1839 | D10: S01-L2-2 | E10: =VLOOKUP(B:B,DATA!A:C,3,0) -> stationery | F10: =VLOOKUP(B:B,DATA!A:D,4,0) -> desk storage | G10: 16
A11: 10 | B11: 1234560056095 | C11: =VLOOKUP(B:B,DATA!A:B,2,0) -> #N/A | D11: S01-L2-2 | E11: =VLOOKUP(B:B,DATA!A:C,3,0) -> #N/A | F11: =VLOOKUP(C:C,DATA!B:D,3,0) -> #N/A | G11: 0
A12: 11 | B12: 1234560056101 | C12: =VLOOKUP(B:B,DATA!A:B,2,0) -> ກັບໃສ່ບິກ GP-5610/6101 | D12: S01-L2-2 | E12: =VLOOKUP(B:B,DATA!A:C,3,0) -> 0 | F12: =VLOOKUP(B:B,DATA!A:D,4,0) -> 0 | G12: 3
A13: 12 | B13: 6972081861785 | C13: =VLOOKUP(B:B,DATA!A:B,2,0) -> ແນວໃສ່ບິກສໍ/DL804/1785 | D13: S01-L1-1 | E13: =VLOOKUP(B:B,DATA!A:C,3,0) -> stationery | F13: =VLOOKUP(B:B,DATA!A:D,4,0) -> desk storage | G13: 0
A14: 13 | B14: 6972543655006 | C14: =VLOOKUP(B:B,DATA!A:B,2,0) -> ຄີບອດດີຈິຕອນ AS212_GP-2479 | D14: S10-L2-3 | E14: =VLOOKUP(B:B,DATA!A:C,3,0) -> TOOL/DIGITAL | F14: =VLOOKUP(B:B,DATA!A:D,4,0) -> computer | G14: 15 | H14: 46044
A15: 14 | B15: 6972081861808 | C15: =VLOOKUP(B:B,DATA!A:B,2,0) -> ແນວໃສ່ບິກສໍ/DL3340/1808 | D15: S01-L1-1 | E15: =VLOOKUP(B:B,DATA!A:C,3,0) -> stationery | F15: =VLOOKUP(B:B,DATA!A:D,4,0) -> desk storage | G15: 0
A16: 15 | B16: 1234560008438 | C16: =VLOOKUP(B:B,DATA!A:B,2,0) -> ແນວໃສ່ບິກສໍ 4ຫ້ອງ /8438 | D16: S01-L1-3 | E16: =VLOOKUP(B:B,DATA!A:C,3,0) -> stationery | F16: =VLOOKUP(B:B,DATA!A:D,4,0) -> desk storage | G16: 17
A17: 16 | B17: 1234560056231 | C17: =VLOOKUP(B:B,DATA!A:B,2,0) -> #N/A | D17: S02-L5-4 | E17: =VLOOKUP(B:B,DATA!A:C,3,0) -> #N/A | F17: =VLOOKUP(B:B,DATA!A:D,4,0) -> #N/A | G17: 6
A18: 17 | B18: 6943538469441 | C18: =VLOOKUP(B:B,DATA!A:B,2,0) -> ກ່ອງໃສ່ບິກສໍ/FQ848/9441 | D18: S01-L2-1 | E18: =VLOOKUP(B:B,DATA!A:C,3,0) -> stationery | F18: =VLOOKUP(B:B,DATA!A:D,4,0) -> desk storage | G18: 14
A19: 18 | B19: 6949066031372 | C19: =VLOOKUP(B:B,DATA!A:B,2,0) -> ກ່ອງປາກກາ/6.5*6.5*10/3137/1372 | D19: S10-L2-3 | E19: =VLOOKUP(B:B,DATA!A:C,3,0) -> BEAUTY | F19: =VLOOKUP(B:B,DATA!A:D,4,0) -> Make up | G19: 10
A20: 19 | B20: 6925188321102 | C20: =VLOOKUP(B:B,DATA!A:B,2,0) -> ກ່ອງໃສ່ບິກສໍ/HS0783 /1102 | D20: S01-L2-3 | E20: =VLOOKUP(B:B,DATA!A:C,3,0) -> stationery | F20: =VLOOKUP(B:B,DATA!A:D,4,0) -> desk storage | G20: 70
A21: 20 | B21: 6972081860863 | C21: =VLOOKUP(B:B,DATA!A:B,2,0) -> ເຄື່ອງເຮັດໃຫ້ມືຊຸ່ມ/DL0530/0863 | D21: S07-l3-1 | E21: =VLOOKUP(B:B,DATA!A:C,3,0) -> stationery | F21: =VLOOKUP(B:B,DATA!A:D,4,0) -> office supplies | G21: 9
A22: 21 | B22: 6986202300251 | C22: =VLOOKUP(B:B,DATA!A:B,2,0) -> ກ່ອງໃສ່ບິກສໍ/HS750 /0251 | D22: S01-L2-4 | E22: =VLOOKUP(B:B,DATA!A:C,3,0) -> stationery | F22: =VLOOKUP(B:B,DATA!A:D,4,0) -> desk storage | G22: 40
A23: 22 | B23: 6972854791516 | C23: =VLOOKUP(B:B,DATA!A:B,2,0) -> ກ່ອງໃສ່ບິກສໍອະເນກປະສົງ/DL3363 /1516 | D23: S01-L3-4 | E23: =VLOOKUP(B:B,DATA!A:C,3,0) -> stationery | F23: =VLOOKUP(B:B,DATA!A:D,4,0) -> desk storage | G23: 36
A24: 23 | B24: 4965534449717 | C24: =VLOOKUP(B:B,DATA!A:B,2,0) -> ກ່ອງໃສ່ອູປະກອບເຄື່ອງໃຊ້ຫ້ອງການ /9717 | D24: S01-L3-1 | E24: =VLOOKUP(B:B,DATA!A:C,3,0) -> TOOL/DIGITAL | F24: =VLOOKUP(B:B,DATA!A:D,4,0) -> hard tools | G24: 14
A25: 24 | B25: 1234560008186 | C25: =VLOOKUP(B:B,DATA!A:B,2,0) -> ແນວວາງນາມບັດ 8CM/H908B/8186 | D25: S01-L3-1 | E25: =VLOOKUP(B:B,DATA!A:C,3,0) -> stationery | F25: =VLOOKUP(B:B,DATA!A:D,4,0) -> desk storage | G25: 3
A26: 25 | B26: 6972854796337 | C26: =VLOOKUP(B:B,DATA!A:B,2,0) -> ກ່ອງໃສ່ບິກສໍ/DL3356/6337 | D26: S01-L3-3 | E26: =VLOOKUP(B:B,DATA!A:C,3,0) -> stationery | F26: =VLOOKUP(B:B,DATA!A:D,4,0) -> desk storage | G26: 5
... A103: 102 | B103: 4550163007386 | C103: =VLOOKUP(B:B,DATA!A:B,2,0) -> ສະກອດ 4mm ຂຽວ/ເຫຼືອງ /7386 | D103: S02-L2-4 | E103: =VLOOKUP(B:B,DATA!A:C,3,0) -> STATIONERY | F103: =VLOOKUP(B:B,DATA!A:D,4,0) -> sticker | G103: 1
A104: 103 | B104: 4550163007393 | C104: =VLOOKUP(B:B,DATA!A:B,2,0) -> ສະກອດ /7393 | E104: =VLOOKUP(B:B,DATA!A:C,3,0) -> STATIONERY | F104: =VLOOKUP(B:B,DATA!A:D,4,0) -> sticker | G104: 0
A105: 104 | B105: 4580682871076 | C105: =VLOOKUP(B:B,DATA!A:B,2,0) -> ສະກອດເຈ້ຍ /1076 | D105: S02-L2-4 | E105: =VLOOKUP(B:B,DATA!A:C,3,0) -> STATIONERY | F105: =VLOOKUP(B:B,DATA!A:D,4,0) -> sticker | G105: 4
A106: 105 | B106: 4580682871151 | C106: =VLOOKUP(B:B,DATA!A:B,2,0) -> ສະກອດເຈ້ຍ /1151 | D106: S02-L2-4 | E106: =VLOOKUP(B:B,DATA!A:C,3,0) -> STATIONERY | F106: =VLOOKUP(B:B,DATA!A:D,4,0) -> sticker | G106: 12
A107: 106 | B107: 4542804083903 | C107: =VLOOKUP(B:B,DATA!A:B,2,0) -> ສາຍໂບ (ຣິບບິ້ນ ສີຟ້າຈາງ) /3903 | D107: S02-L2-4 | E107: =VLOOKUP(B:B,DATA!A:C,3,0) -> STATIONERY | F107: =VLOOKUP(B:B,DATA!A:D,4,0) -> Packaging supplies | G107: 0
A108: 107 | B108: 4979142119719 | C108: =VLOOKUP(B:B,DATA!A:B,2,0) -> ກໍ້ເຈັ້ຍໂນສ ໄຮໄລ /9719 | D108: S02-L2-4 | E108: =VLOOKUP(B:B,DATA!A:C,3,0) -> STATIONERY | F108: =VLOOKUP(B:B,DATA!A:D,4,0) -> office supplies | G108: 18
A109: 108 | B109: 4560116775392 | C109: =VLOOKUP(B:B,DATA!A:B,2,0) -> ສະກອດ MKT-1 /5392 | D109: S02-L2-4 | E109: =VLOOKUP(B:B,DATA!A:C,3,0) -> STATIONERY | F109: =VLOOKUP(B:B,DATA!A:D,4,0) -> sticker | G109: 1
A110: 109 | B110: 4580682872004 | C110: =VLOOKUP(B:B,DATA!A:B,2,0) -> ສະກອດເຈ້ຍ /2004 | D110: S02-L2-4 | E110: =VLOOKUP(B:B,DATA!A:C,3,0) -> STATIONERY | F110: =VLOOKUP(B:B,DATA!A:D,4,0) -> sticker | G110: 2
A111: 110 | B111: 4542804132724 | C111: =VLOOKUP(B:B,DATA!A:B,2,0) -> ສະກອດພີມລາຍ 20mm*4m /2724 | D111: S02-L2-4 | E111: =VLOOKUP(B:B,DATA!A:C,3,0) -> STATIONERY | F111: =VLOOKUP(B:B,DATA!A:D,4,0) -> sticker | G111: 0
A112: 111 | B112: 4979142708203 | C112: =VLOOKUP(B:B,DATA!A:B,2,0) -> ສາຍໂບ ຣິບບິ້ນ ສີມ້ວງ /8203 | D112: S02-L2-4 | E112: =VLOOKUP(B:B,DATA!A:C,3,0) -> STATIONERY | F112: =VLOOKUP(B:B,DATA!A:D,4,0) -> Packaging supplies | G112: 4
A113: 112 | B113: 4580682871113 | C113: =VLOOKUP(B:B,DATA!A:B,2,0) -> ສະກອດເຈ້ຍ /1113 | D113: S05-L3-3 | E113: =VLOOKUP(B:B,DATA!A:C,3,0) -> STATIONERY | F113: =VLOOKUP(B:B,DATA!A:D,4,0) -> sticker | G113: 1
A114: 113 | B114: 4978929317645 | C114: =VLOOKUP(B:B,DATA!A:B,2,0) -> ສະຕິກເກີ້ /7645 | D114: S05-L3-3 | E114: =VLOOKUP(B:B,DATA!A:C,3,0) -> STATIONERY | F114: =VLOOKUP(B:B,DATA!A:D,4,0) -> art supplies | G114: 3
A115: 114 | B115: 4978929318499 | C115: =VLOOKUP(B:B,DATA!A:B,2,0) -> ສະຕິກເກີ້ /8499 | D115: S02-L2-4 | E115: =VLOOKUP(B:B,DATA!A:C,3,0) -> STATIONERY | F115: =VLOOKUP(B:B,DATA!A:D,4,0) -> art supplies | G115: 0
A116: 115 | B116: 4542804083910 | C116: =VLOOKUP(B:B,DATA!A:B,2,0) -> ສາຍໂບ (ຣິບບິ້ນ ສີທອງ) /3910 | D116: S05-L3-3 | E116: =VLOOKUP(B:B,DATA!A:C,3,0) -> STATIONERY | F116: =VLOOKUP(B:B,DATA!A:D,4,0) -> Packaging supplies | G116: 0
...

Sheet DATA
A1: Barcode | B1: Product Name(LA) | C1: CATEGORIES 1 | D1: CATEGORIES 2
A2: 4535792404577 | B2: ຖົງໃສ່ເຄື່ອງ (ໃຫຍ່) /4577 | C2: BEAUTY | D2: bag
A3: 4535792405697 | B3: ຖົງຊິບຫິ້ວເຄື່ອງ /5697 | C3: FASHION | D3: bag
A4: 4535792216576 | B4: ຖົງ ອາລູມີ້ ເກັບອູນຫະພູມ /6576 | C4: KITCHEN | D4: glass/cup/water/bottle
A5: 4535792363089 | B5: ຖົງພາຍໃສ່ເຄື່ອງ /3089 | C5: FASHION | D5: bag
A6: 4535792389027 | B6: ຖົງໃສ່ເຄື່ອງ (ໃຫຍ່) /9027 | C6: BEAUTY | D6: bag
A7: 4535792383575 | B7: ຖົງຫິ້ວເຄື່ອງ /3575 | C7: FASHION | D7: bag
A8: 4535792383568 | B8: ຖົງຫິ້ວເຄື່ອງ /3568 | C8: FASHION | D8: bag
A9: 4535792380024 | B9: ຖົງເທົ້າຍິງ /0024 | C9: FASHION | D9: socks and others
A10: 4535792370193 | B10: ຖົງເທົ້າຍິງ /0193 | C10: FASHION | D10: socks and others
A11: 4535792388488 | B11: ຖົງເທົ້າຍິງ /8488 | C11: FASHION | D11: socks and others
A12: 4535792313541 | B12: ຜ້າກັ້ງປ່ອງອາຫານສຳລັບ ຄ່າເຟ/3541 | C12: INTERIOR | D12: curtain
... A101: 4560193004095 | B101: ເຈ້ຍທິດຊູ້ 240 /4095 | C101: BEAUTY | D101: tissues
A102: 8309281355328 | B102: (24-29) ເກີບ/PK388 B1/355328 | C102: 0 | D102: 0
A103: 4562220838826 | B103: ສາຍສາກໂທລະສັບ 2 ແມັດ /8826 | C103: TOOL/DIGITAL | D103: MOBILE PHONE ACCESSORIES
A104: 4562220838819 | B104: ສາຍສາກໂທລະສັບ 2 ແມັດ /8819 | C104: TOOL/DIGITAL | D104: MOBILE PHONE ACCESSORIES
A105: 4560348442321 | B105: ຫົວອາແດ໊ບເຕີ້ 2.4A Type-C-iPhone Adaptor /2321 | C105: TOOL/DIGITAL | D105: MOBILE PHONE ACCESSORIES
A106: 4560348442314 | B106: ສາຍສາກໂທລະສັບໄອໂຟນ 2.4A Type-C /2314 | C106: TOOL/DIGITAL | D106: MOBILE PHONE ACCESSORIES
A107: 4562220838925 | B107: ສາຍສາກໂທລະສັບ Type-C LED /8925 | C107: TOOL/DIGITAL | D107: MOBILE PHONE ACCESSORIES
A108: 4562220838932 | B108: ສາຍສາກໂທລະສັບ Type-C LED /8932 | C108: TOOL/DIGITAL | D108: MOBILE PHONE ACCESSORIES
A109: 4562220838949 | B109: ສາຍສາກໂທລະສັບ Type-C LED /8949 | C109: TOOL/DIGITAL | D109: MOBILE PHONE ACCESSORIES
A110: 4560348442338 | B110: ສາຍສາກໂທລະສັບໄອໂຟນ /2338 | C110: TOOL/DIGITAL | D110: MOBILE PHONE ACCESSORIES
A111: 6972856740154 | B111: ບິກສີນ້ຳ24ສີ/DQ-201-24 /0154 | C111: stationery | D111: Art supplies
A112: 6972856740161 | B112: ບິກສີນ້ຳ24ສີ/DQ-202-24 /0161 | C112: stationery | D112: Art supplies
A113: 4969757154229 | B113: ປື້ມແຕ້ມອອກແບບ 253*352mm 10 ໃບ /4229 | C113: STATIONERY | D113: art supplies
A114: 4982790389083 | B114: ຂໍເກາະ 2.5CM /9083 | C114: STORAGE | D114: hanger/hook
... A170: 4982592304116 | B170: ເຊືອກມັດ 35m /4116 | C170: TOOL/DIGITAL | D170: gardening tools
A171: 8039375035570 | B171: (36-40) ເກີບ /PK1310-1/35570 | C171: 0 | D171: 0
A172: 8825003842379 | B172: (36-40) ເກີບ /PK1310-3/842379 | C172: 0 | D172: 0
A173: 4905656117347 | B173: ຂອງຫຼິ້ນມາຍາກົນ /7347 | C173: STATIONERY | D173: toy others
A174: 4905656118900 | B174: ຂອງຫຼິ້ນມາຍາກົນ /8900 | C174: STATIONERY | D174: toy others
A175: 4560348442352 | B175: ສາຍສາກໂທລະສັບໄອໂຟນ Type-C /2352 | C175: TOOL/DIGITAL | D175: MOBILE PHONE ACCESSORIES
A176: 4978929520403 | B176: ປຸມເປົ້າ ເລກ 3 /0403 | C176: STATIONERY | D176: toy others
A177: 4982790389076 | B177: ຂໍເກາະ 6 ຂໍ 3CM /9076 | C177: STORAGE | D177: hanger/hook
A178: 4904342004749 | B178: ສໍໄສ້ /4749 | C178: STATIONERY | D178: school supplies
A179: 4971665047913 | B179: ແຜ່ນປະກອບຮູບ 3D /7913 | C179: TOYS | D179: toy others
A180: 4580682872431 | B180: ຜ້າປິດປາກ 3D /2431 | C180: BEAUTY | D180: home medical supplies
A181: 4979142142564 | B181: ສາຍໂບ ຣິບບິ້ນ /2564 | C181: STATIONERY | D181: Packaging supplies
A182: 6971091797084 | B182: ກາວຮ້ອນຂາວ3ແທ່ງ ສັ້ນ ແລະ ຫນາ /7084 | C182: STORAGE | D182: basket
A183: 4979142117227 | B183: ໄມ້ອັດ ໂຕຫນັງສື 3 /7227 | C183: INTERIOR | D183: home interior
...

Sheet Map Layout
L2: Cleaning/Bath
B3: S04-L4 | E3: S07-L4 | G3: S08-L4 | L3: A01-L4 | O3: A02-L4 | R3: A03-L4 | U3: A04-L4 | X3: A05-L4
B4: S04-L3 | E4: S07-L3 | G4: S08-L3 | L4: A01-L3 | O4: A02-L3 | R4: A03-L3 | U4: A04-L3 | X4: A05-L3
B5: S04-L2 | E5: S07-L2 | G5: S08-L2 | L5: A01-L2 | O5: A02-L2 | R5: A03-L2 | U5: A04-L2 | X5: A05-L2
B6: S04-L1 | E6: S07-L1 | G6: S08-L1 | L6: A01-L1 | O6: A02-L1 | R6: A03-L1 | U6: A04-L1 | X6: A05-L1
B7: S03-L4
B8: S03-L3 | E8: S05-L4 | G8: S06-L4 | L8: B04-L4 | N8: C03-L4 | P8: D03-L4 | Q8: D06-L4 | S8: E04-L4 | T8: F04-L4 | V8: G04-L4 | W8: G08-L4 | Y8: H04-L4 | Z8: Sport Leisure
B9: S03-L2 | E9: S05-L3 | G9: S06-L3 | L9: B04-L3 | N9: C03-L3 | P9: D03-L3 | Q9: D06-L3 | S9: E04-L3 | T9: F04-L3 | V9: G04-L3 | W9: G08-L3 | Y9: H04-L3
B10: S03-L1 | E10: S05-L2 | G10: S06-L2 | L10: B04-L2 | N10: C03-L2 | P10: D03-L2 | Q10: D06-L2 | S10: E04-L2 | T10: F04-L2 | V10: G04-L2 | W10: G08-L2 | Y10: H04-L2
E11: S05-L1 | G11: S06-L1 | L11: B04-L1 | N11: C03-L1 | P11: D03-L1 | Q11: D06-L1 | S11: E04-L1 | T11: F04-L1 | V11: G04-L1 | W11: G08-L1 | Y11: H04-L1
B12: S02-L4
B13: S02-L3 | E13: Stationery | L13: B03-L4 | N13: C02-L4 | P13: D02-L4 | Q13: D05-L4 | S13: E03-L4 | T13: F03-L4 | V13: G03-L4 | W13: G07-L4 | Y13: H03-L4
B14: S02-L2 | L14: B03-L3 | N14: C02-L3 | P14: D02-L3 | Q14: D05-L3 | S14: E03-L3 | T14: F03-L3 | V14: G03-L3 | W14: G07-L3 | Y14: H03-L3
B15: S02-L1 | I15: Door | L15: B03-L2 | N15: C02-L2 | P15: D02-L2 | Q15: D05-L2 | S15: E03-L2 | T15: F03-L2 | V15: G03-L2 | W15: G07-L2 | Y15: H03-L2
B16: S01-L4 | L16: B03-L1 | N16: C02-L1 | P16: D02-L1 | Q16: D05-L1 | S16: E03-L1 | T16: F03-L1 | V16: G03-L1 | W16: G07-L1 | Y16: H03-L1
B17: S01-L3
B18: S01-L2 | L18: B02-L4 | N18: C01-L4 | P18: D01-L4 | Q18: D04-L4 | S18: E02-L4 | T18: F02-L4 | V18: G02-L4 | W18: G06-L4 | Y18: H02-L4 | Z18: Toys
B19: S01-L1 | L19: B02-L3 | N19: C01-L3 | P19: D01-L3 | Q19: D04-L3 | S19: E02-L3 | T19: F02-L3 | V19: G02-L3 | W19: G06-L3 | Y19: H02-L3
L20: B02-L2 | N20: C01-L2 | P20: D01-L2 | Q20: D04-L2 | S20: E02-L2 | T20: F02-L2 | V20: G02-L2 | W20: G06-L2 | Y20: H02-L2
E21: Door | L21: B02-L1 | N21: C01-L1 | P21: D01-L1 | Q21: D04-L1 | S21: E02-L1 | T21: F02-L1 | V21: G02-L1 | W21: G06-L1 | Y21: H02-L1
N22: Fasion | P22: Storage
B23: P01-L3 | C23: P02-L3 | G23: P03-L3 | H23: P04-L3 | I23: P05-L3 | L23: B01-L4 | S23: E01-L4 | T23: F01-L4 | V23: G01-L4 | W23: G05-L4 | Y23: H01-L4
B24: P01-L2 | C24: P02-L2 | G24: P03-L2 | H24: P04-L2 | I24: P05-L2 | L24: B01-L3 | S24: E01-L3 | T24: F01-L3 | V24: G01-L3 | W24: G05-L3 | Y24: H01-L3
B25: P01-L1 | C25: P02-L1 | G25: P03-L1 | H25: P04-L1 | I25: P05-L1 | L25: B01-L2 | S25: E01-L2 | T25: F01-L2 | V25: G01-L2 | W25: G05-L2 | Y25: H01-L2
B26: Paper Tissue | G26: Paper Tissue | L26: B01-L1 | S26: E01-L1 | T26: F01-L1 | V26: G01-L1 | W26: G05-L1 | Y26: H01-L1
L27: Interior | S27: Beauty | T27: Tool Digital | V27: Kitchen
L30: I01-L1 | Q30: Sport Leisure Toys | X30: AM Working Position

Sheet Sheet1
A1: 4542804129373 | B1: 10
A2: 4944371423104 | B2: 12
A3: 4982592013667 | B3: 20
A4: 4968988023878 | B4: 40
A5: 4580104601526 | B5: 10
A6: 4526112556861 | B6: 12
A7: 4580682871113 | B7: 12
A8: 4582281741538 | B8: 20
A9: 4902505637070 | B9: 20
A10: 4980299066542 | B10: 12
A11: 4980299036347 | B11: 6
A12: 4980299020629 | B12: 12
... A605: 6951109368406 | B605: 12
